Workbook

Sheet Broker Fees
A1: Broker fee reference — verify current schedules before acting; brokers change pricing without much notice
A3: Broker | B3: Stock/ETF Commission | C3: Custody Fee (annual) | D3: Custody Fee Notes | E3: FX Conversion Fee | F3: Inactivity Fee | G3: Min Deposit (approx, USD equiv) | H3: Source / Last Checked | I3: UK ISA Offered?
A4: IBKR | B4: US stocks: $0.0035/share, min $0.35 (Pro, Tiered). IBKR Lite (US residents/Singapore only): $0 on US-listed stocks/ETFs. | C4: 0 | D4: No custody fee (any account size). | E4: 0.03 | F4: None (eliminated 2021). UK Stocks & Shares ISA: GBP 3/month. | G4: 0 | H4: interactivebrokers.com pricing & fact sheet, checked Jun 2026 | I4: Yes (GBP 3/month fee)
A5: Saxo | B5: Classic: 0.08% of trade value, min ~$1 (US) / €2 (EU stocks). | C5: 0.15 | D5: 0.15%/yr + 25% Danish VAT (non-EU clients); removed on core EU retail accounts since Feb 2025 restructuring — verify for your entity. | E5: 0.25 | F5: None. | G5: 0 | H5: home.saxo rates & conditions; brokerchooser, thepoorswiss, checked Jun 2026 | I5: Yes (0.12% custody + 0.08% commission)
A6: Wio | B6: 0% commission marketed on US & UAE stocks (revenue via FX spread, not published as a clean bps figure). | C6: 0 | D6: No stated custody fee. | E6: Not disclosed | F6: Not publicly disclosed. | G6: 0 | H6: wioinvest.io, vaultwealth.com comparison, checked 2026 | I6: No (UAE-only, not applicable)
A7: Exante | B7: US stocks: $0.02/share, min $1 for first 1-50 shares/order. | C7: 0 | D7: No custody fee for stocks/ETFs per most 2026 reviews (one support article mentions a 0.3%/yr custody fee context possibly tied to bonds — confirm on your account's fee schedule). | E7: 0 | F7: EUR 50/6 months if no trades AND balance < EUR 5,000. | G7: 10000 | H7: support.exante.eu fee pages; tradersunion, sharecast, checked 2026. Does not accept US, Japan, Iran, North Korea residents. | I7: Not offered, based on available info
A8: Swissquote | B8: CHF 3 (trades up to CHF 500) to CHF 25-29 (larger tickets), tiered by order size. | C8: 0 | D8: Tiered flat quarterly fee, not a clean % — CHF 20/quarter (up to CHF 50k) rising to a CHF 50/quarter cap (CHF 150k-1m); above CHF 1m add 0.0075%/quarter. | E8: 0.95 | F8: Applies to forex/CFD accounts only per some sources, not plain stock accounts — confirm for your account type. | G8: 1000 | H8: swissquote.com account fees, brokerchooser, thepoorswiss, checked Jun 2026 | I8: Not offered, based on available info
A9: XTB | B9: 0% on real stocks/ETFs up to EUR 100,000 turnover/month; 0.2% (min EUR 10) above that. | C9: 0 | D9: No custody fee. | E9: 0.5 | F9: EUR 10/month after 365 days with no trade AND 90 days with no deposit. | G9: 0 | H9: xtb.com fees & commissions table, brokerchooser, quantroutine, checked 2026 | I9: Yes (free — no extra fee)

Sheet Fee Reduction Tactics
A1: How to actually lower each broker's fees — real, broker-specific levers you control
A3: Broker | B3: What reduces YOUR fees | C3: Watch out for
A4: IBKR | B4: Use IBKR Lite (US residents/Singapore only) for $0 commission on US-listed stocks/ETFs instead of Pro. Keep cash >$100,000 NAV to get the top interest tier on idle cash. Trade in the instrument's native currency to minimize the ~0.03% FX conversion. Use a General Investment Account rather than the UK Stocks & Shares ISA if you don't need the wrapper — the ISA carries a GBP 3/month fee the standard account doesn't. | C4: IBKR Lite gives worse order routing and a higher margin markup (2.5% vs 0.5-1.5% on Pro) — a false economy if you ever use margin.
A5: Saxo | B5: Enable the stock-lending program to waive the 0.15%/yr custody fee entirely (Saxo splits the lending revenue with you 50/50). Where Saxo has removed custody fees on 'core EU' retail accounts, you already pay 0. Keep trade sizes above ~$2,500/€2,500 so the 0.08% commission clears the flat minimum rather than being dominated by it. Use the UK Stocks & Shares ISA (0.12% custody, 0.08% commission) to shelter gains from UK CGT. | C5: Stock lending exposes your shares to counterparty/recall risk in exchange for the fee waiver — read the terms before opting in.
A6: Wio | B6: Fund and trade in AED or USD to avoid unnecessary conversions, since Wio's cost is an undisclosed FX spread rather than a stated commission. | C6: Because the spread isn't published as a clean bps figure, you can't easily verify you're getting a fair rate — compare a live quote against IBKR/XTB before a large trade.
A7: Exante | B7: Keep your balance above EUR 5,000 and place at least one trade every 6 months to avoid the EUR 50 inactivity fee. Fund via bank wire (the only method) rather than triggering avoidable processing fees; use the debit card for spending instead of frequent withdrawals (EUR 30 flat fee each). | C7: The EUR 10,000 minimum deposit is a real barrier — this isn't cost-effective for small portfolios regardless of tactics.
A8: Swissquote | B8: Stick to the 'ETF Leaders' list on the SIX exchange — capped at CHF 9/trade regardless of size, versus the standard tiered commission. Let your custody account value grow past CHF 150,000 to hit the CHF 50/quarter (CHF 200/year) cap rather than paying the % rate on a small portfolio. Hold CHF/EUR/USD clearing accounts and fund/trade in matching currencies to avoid the 0.95% FX conversion where possible. | C8: Below CHF 150,000 the flat quarterly custody fee (CHF 20-37.50) is a bigger drag in percentage terms on a small portfolio — run the numbers against a zero-custody-fee alternative first.
A9: XTB | B9: Stay under EUR 100,000 traded (buys+sells) per calendar month to keep 0% commission on real stocks/ETFs. Hold a base-currency account matching your main instruments to avoid the 0.5% FX markup. Keep at least one trade every 365 days and one deposit every 90 days to dodge the EUR 10/month inactivity fee. Use the UK Flexible Stocks & Shares ISA (0% commission under the same monthly cap, no custody fee) to shelter UK gains. | C9: The EUR 100,000/month cap is on total turnover (buys + sells combined), not net investment — frequent rebalancing can push you over it faster than expected.

Sheet Tax Reduction Levers
A1: What actually lowers your tax bill by tax residency — none of this is 'pick a cheaper broker'; it's wrappers, product choice, and how you invest
A3: Tax Residency | B3: Real, legitimate levers | C3: What does NOT work
A4: US | B4: Hold positions >1 year to qualify for 0/15/20% long-term rates instead of ordinary income rates up to 37%. Use tax-loss harvesting (IBKR's PortfolioAnalyst Tax Planner can model this) to offset gains with losses, and up to $3,000/year of excess losses against ordinary income. Manage the timing of realizations to stay under NIIT thresholds ($200k single/$250k joint MAGI) where possible. Use tax-advantaged wrappers (401(k), IRA, Roth IRA) for the portion of investing that fits inside them — none of these six brokers offer US retirement wrappers directly, so this typically means a separate custodian. | C4: Switching between IBKR/Saxo/etc. does not change your federal LTCG bracket or NIIT exposure — those depend on your income and holding period, not your broker.
A5: UK | B5: Use a Stocks & Shares ISA — IBKR, Saxo, and XTB all offer one among these six brokers — to shelter up to £20,000/year of contributions from CGT and dividend tax entirely, indefinitely. Use your £3,000 Annual Exempt Amount every year (it doesn't carry forward). Where you're near the basic/higher-rate boundary, timing a disposal to a lower-income year can keep more of the gain at 18% instead of 24%. | C5: Wio, Exante, and Swissquote do not appear to offer a UK ISA — gains there sit in a fully taxable general account regardless of that broker's fee schedule.
A6: EU | B6: This depends entirely on which EU country you're resident in — the single biggest 'lever' is your actual country of tax residence, not your broker. Some countries (e.g. Germany) offer a small annual tax-free allowance (Sparerpauschbetrag, €1,000/person) that a domestic bank applies automatically via a Freistellungsauftrag; a foreign broker like these six usually won't apply it for you, so you self-report and reclaim it via your tax return instead. Choosing UCITS ETFs suited to your specific country's fund-taxation regime (e.g. Germany's Teilfreistellung partial exemption for equity funds) can reduce the effective rate on that category of holding. | C6: None of these six brokers apply your home country's tax-free allowances automatically the way a domestic bank might — you're responsible for declaring and claiming them yourself.
A7: UAE | B7: None needed — already 0% for individuals. The only 'lever' is making sure you're genuinely UAE tax resident and not still tax resident (and therefore taxable) somewhere else under that other country's rules. | C7: There's no fee/tax combination among these six brokers that improves on 0%; broker choice here is purely about fees, product access, and service quality.
A8: CH | B8: Meet all 5 of the Circular No. 36 private-investor safe-harbour criteria to keep the 0% rate on securities gains: hold each position ≥ 6 months, keep annual trading volume ≤ 5x your portfolio value, keep realized gains < 50% of net income, don't use borrowed money to invest, and only use derivatives for hedging. Breaching these risks reclassification as a 'professional securities trader', taxing the same gains as ordinary income plus social security contributions. | C8: This is about how you invest (holding period, leverage, turnover), not which of these six brokers executes the trades — a broker cannot make you a 'private investor' if your trading pattern says otherwise.
A9: UA | B9: Ukraine credits foreign tax already withheld on the same income against your 18% PIT liability (the 5% military levy is payable regardless) — make sure any foreign withholding tax deducted at source is properly documented so you can claim the credit and avoid double taxation. Keep clean records since Ukrainian brokers don't act as a tax agent for foreign securities — you self-declare and pay annually. | C9: None of these six brokers reduce the 23% combined rate on capital gains from securities — that's fixed by Ukrainian tax law regardless of custodian.

Sheet Tax Residency Eligibility
A1: Which of these brokers actually accept clients from each tax residency (as of mid-2026) — always confirm on the broker's own site, this changes often
A3: Broker | B3: US | C3: UK | D3: EU | E3: UAE | F3: CH | G3: UA
A4: IBKR | B4: Y | C4: Y | D4: Y | E4: Y | F4: Y | G4: Y
A5: Saxo | B5: N | C5: Y | D5: Y | E5: Y | F5: Y | G5: N
A6: Wio | B6: N | C6: N | D6: N | E6: Y | F6: N | G6: N
A7: Exante | B7: N | C7: Y | D7: Y | E7: Y | F7: Y | G7: Check
A8: Swissquote | B8: N | C8: Y | D8: Y | E8: Y | F8: Y | G8: Check
A9: XTB | B9: N | C9: Y | D9: Y | E9: Y | F9: Y | G9: Y
A11: Note | B11: US: only IBKR among these six accepts US-tax resident clients directly (IBKR Lite for US stocks/ETFs, or IBKR Pro). Saxo, Wio, Exante, Swissquote and XTB all explicitly exclude US persons.
A12: Note | B12: UAE: all six accept UAE tax residents (Wio requires a UAE Wio Personal bank account + Emirates ID/visa).
A13: Note | B13: Ukraine (UA): IBKR and XTB confirmed available. Saxo stopped onboarding Ukraine tax residents from 1 July 2024. Exante and Swissquote have conflicting/unclear public info for Ukraine tax residency — contact them directly before assuming access.
A14: Note | B14: Wio is a UAE-only digital bank/broker — not available to any other tax residency in this list.
A15: Note | B15: 'EU' and 'CH' rows assume a mainstream EU country and Switzerland; exact coverage still varies by specific country and by broker entity (e.g. XTB excludes Belgium; Saxo stopped several EU/EEA countries in 2024).
A17: Note | B17: "Tax residency" is not the same as citizenship or physical/day-to-day location. It is the country where you are legally liable to pay tax, determined by rules such as days present, center of vital interests, or domicile — these vary by country. A person can live in one country while being tax-resident in another.
A18: Note | B18: Broker availability is not universal: a broker eligible for a client's tax residency here does not guarantee availability of every account type, product, or wrapper (e.g. ISA) in that residency — always check the specific entity onboarding the client.

Sheet Capital Gains Tax
A1: Capital gains tax by tax residency — this does NOT depend on which broker you use; broker choice cannot change your statutory tax rate
A3: Tax Residency | B3: Typical Rate — Low | C3: Typical Rate — High | D3: Notes / Basis
A4: US | B4: 0 | C4: 0.238 | D4: Federal long-term capital gains: 0% / 15% / 20% by taxable income bracket (2026: 0% up to ~$48,350 single/$96,700 joint; 20% above ~$533,400/$600,050). Add 3.8% Net Investment Income Tax (NIIT) above $200,000 single / $250,000 joint MAGI — worst case ~23.8%. Short-term gains (held ≤ 1 year) are taxed as ordinary income up to 37% (+3.8% NIIT = ~40.8%). State tax may add more (e.g. California up to 13.3%). Source: IRS Rev. Proc. 2025-32/40, checked Jun 2026.
A5: UK | B5: 0.18 | C5: 0.24 | D5: 18% for basic-rate taxpayers, 24% for higher/additional-rate taxpayers, on shares/funds/crypto and property alike since the 30 Oct 2024 Budget. £3,000 annual tax-free allowance (Annual Exempt Amount) per person, use-it-or-lose-it. Source: gov.uk CGT rates, checked Jun 2026.
A6: EU | B6: 0 | C6: 0.314 | D6: 'EU' is not one jurisdiction — treatment ranges from 0% (Belgium general regime, Netherlands taxes deemed return on wealth rather than realised share gains) to Germany's 26.375% flat Abgeltungsteuer (25% + solidarity surcharge) to France's 30% PFU flat tax (rising to ~31.4% effective with 2026 social-charge changes). Use your specific EU country's rate, not a bloc average.
A7: UAE | B7: 0 | C7: 0 | D7: No personal income or capital gains tax for individuals. Genuinely broker-independent.
A8: CH | B8: 0 | C8: 0 | D8: Private capital gains on shares/ETFs/bonds/crypto are exempt from federal, cantonal and municipal tax under Art. 16(3) DBG — provided you meet the 5 'safe harbour' private-investor criteria in Circular No. 36 (hold ≥ 6 months, annual turnover ≤ 5x portfolio, gains < 50% of net income, no leverage, derivatives only for hedging). If reclassified as a professional securities trader, gains are taxed as ordinary income instead (plus social security contributions).
A9: UA | B9: 0.23 | C9: 0.23 | D9: 18% personal income tax + 5% wartime military levy (raised from 1.5% in Dec 2024) = 23% on capital gains from securities/investment assets. Ukraine-source dividends from Ukrainian CIT-paying companies get a lower combined ~6.5% rate; this 23% is for capital gains specifically.

Sheet Broker Combinations
A1: 1-3 broker combinations by tax residency — eligibility, combined minimum deposit, and the applicable capital-gains tax range (tax depends only on tax residency, not broker)
A3: Tax Residency | B3: Broker_Combo | C3: Broker1 | D3: Broker2 | E3: Broker3 | F3: All_Eligible | G3: Combined_Min_Deposit (approx USD) | H3: Notes | I3: Capital Gains Tax — Low | J3: Capital Gains Tax — High
A4: US | B4: IBKR | C4: IBKR | F4: =IF(OR(IF(C4="","", IFERROR(INDEX('Tax Residency Eligibility'!$B$4:$G$9,MATCH(C4,'Tax Residency Eligibility'!$A$4:$A$9,0),MATCH($A4,'Tax Residency Eligibility'!$B$3:$G$3,0)),"?"))="N",IF(D4="","", IFERROR(INDEX('Tax Residency Eligibility'!$B$4:$G$9,MATCH(D4,'Tax Residency Eligibility'!$A$4:$A$9,0),MATCH($A4,'Tax Residency Eligibility'!$B$3:$G$3,0)),"?"))="N",IF(E4="","", IFERROR(INDEX('Tax Residency Eligibility'!$B$4:$G$9,MATCH(E4,'Tax Residency Eligibility'!$A$4:$A$9,0),MATCH($A4,'Tax Residency Eligibility'!$B$3:$G$3,0)),"?"))="N"),"No",IF(OR(IF(C4="","", IFERROR(INDEX('Tax Residency Eligibility'!$B$4:$G$9,MATCH(C4,'Tax Residency Eligibility'!$A$4:$A$9,0),MATCH($A4,'Tax Residency Eligibility'!$B$3:$G$3,0)),"?"))="Check",IF(D4="","", IFERROR(INDEX('Tax Residency Eligibility'!$B$4:$G$9,MATCH(D4,'Tax Residency Eligibility'!$A$4:$A$9,0),MATCH($A4,'Tax Residency Eligibility'!$B$3:$G$3,0)),"?"))="Check",IF(E4="","", IFERROR(INDEX('Tax Residency Eligibility'!$B$4:$G$9,MATCH(E4,'Tax Residency Eligibility'!$A$4:$A$9,0),MATCH($A4,'Tax Residency Eligibility'!$B$3:$G$3,0)),"?"))="Check"),"Check directly","Yes")) | G4: =IFERROR(VLOOKUP(C4,'Broker Fees'!$A$4:$G$9,7,0),0)+IF(D4="",0,IFERROR(VLOOKUP(D4,'Broker Fees'!$A$4:$G$9,7,0),0))+IF(E4="",0,IFERROR(VLOOKUP(E4,'Broker Fees'!$A$4:$G$9,7,0),0)) | H4: Opening all brokers in this combo means meeting each one's minimum deposit separately (this column sums them) and paying each broker's own commission/custody/FX schedule — see Broker Fees sheet. Diversifying across brokers does not lower any individual fee. | I4: =VLOOKUP($A4,'Capital Gains Tax'!$A$4:$D$9,2,0) | J4: =VLOOKUP($A4,'Capital Gains Tax'!$A$4:$D$9,3,0)
A5: US | B5: Saxo | C5: Saxo | F5: =IF(OR(IF(C5="","", IFERROR(INDEX('Tax Residency Eligibility'!$B$4:$G$9,MATCH(C5,'Tax Residency Eligibility'!$A$4:$A$9,0),MATCH($A5,'Tax Residency Eligibility'!$B$3:$G$3,0)),"?"))="N",IF(D5="","", IFERROR(INDEX('Tax Residency Eligibility'!$B$4:$G$9,MATCH(D5,'Tax Residency Eligibility'!$A$4:$A$9,0),MATCH($A5,'Tax Residency Eligibility'!$B$3:$G$3,0)),"?"))="N",IF(E5="","", IFERROR(INDEX('Tax Residency Eligibility'!$B$4:$G$9,MATCH(E5,'Tax Residency Eligibility'!$A$4:$A$9,0),MATCH($A5,'Tax Residency Eligibility'!$B$3:$G$3,0)),"?"))="N"),"No",IF(OR(IF(C5="","", IFERROR(INDEX('Tax Residency Eligibility'!$B$4:$G$9,MATCH(C5,'Tax Residency Eligibility'!$A$4:$A$9,0),MATCH($A5,'Tax Residency Eligibility'!$B$3:$G$3,0)),"?"))="Check",IF(D5="","", IFERROR(INDEX('Tax Residency Eligibility'!$B$4:$G$9,MATCH(D5,'Tax Residency Eligibility'!$A$4:$A$9,0),MATCH($A5,'Tax Residency Eligibility'!$B$3:$G$3,0)),"?"))="Check",IF(E5="","", IFERROR(INDEX('Tax Residency Eligibility'!$B$4:$G$9,MATCH(E5,'Tax Residency Eligibility'!$A$4:$A$9,0),MATCH($A5,'Tax Residency Eligibility'!$B$3:$G$3,0)),"?"))="Check"),"Check directly","Yes")) | G5: =IFERROR(VLOOKUP(C5,'Broker Fees'!$A$4:$G$9,7,0),0)+IF(D5="",0,IFERROR(VLOOKUP(D5,'Broker Fees'!$A$4:$G$9,7,0),0))+IF(E5="",0,IFERROR(VLOOKUP(E5,'Broker Fees'!$A$4:$G$9,7,0),0)) | H5: Opening all brokers in this combo means meeting each one's minimum deposit separately (this column sums them) and paying each broker's own commission/custody/FX schedule — see Broker Fees sheet. Diversifying across brokers does not lower any individual fee. | I5: =VLOOKUP($A5,'Capital Gains Tax'!$A$4:$D$9,2,0) | J5: =VLOOKUP($A5,'Capital Gains Tax'!$A$4:$D$9,3,0)
A6: US | B6: Wio | C6: Wio | F6: =IF(OR(IF(C6="","", IFERROR(INDEX('Tax Residency Eligibility'!$B$4:$G$9,MATCH(C6,'Tax Residency Eligibility'!$A$4:$A$9,0),MATCH($A6,'Tax Residency Eligibility'!$B$3:$G$3,0)),"?"))="N",IF(D6="","", IFERROR(INDEX('Tax Residency Eligibility'!$B$4:$G$9,MATCH(D6,'Tax Residency Eligibility'!$A$4:$A$9,0),MATCH($A6,'Tax Residency Eligibility'!$B$3:$G$3,0)),"?"))="N",IF(E6="","", IFERROR(INDEX('Tax Residency Eligibility'!$B$4:$G$9,MATCH(E6,'Tax Residency Eligibility'!$A$4:$A$9,0),MATCH($A6,'Tax Residency Eligibility'!$B$3:$G$3,0)),"?"))="N"),"No",IF(OR(IF(C6="","", IFERROR(INDEX('Tax Residency Eligibility'!$B$4:$G$9,MATCH(C6,'Tax Residency Eligibility'!$A$4:$A$9,0),MATCH($A6,'Tax Residency Eligibility'!$B$3:$G$3,0)),"?"))="Check",IF(D6="","", IFERROR(INDEX('Tax Residency Eligibility'!$B$4:$G$9,MATCH(D6,'Tax Residency Eligibility'!$A$4:$A$9,0),MATCH($A6,'Tax Residency Eligibility'!$B$3:$G$3,0)),"?"))="Check",IF(E6="","", IFERROR(INDEX('Tax Residency Eligibility'!$B$4:$G$9,MATCH(E6,'Tax Residency Eligibility'!$A$4:$A$9,0),MATCH($A6,'Tax Residency Eligibility'!$B$3:$G$3,0)),"?"))="Check"),"Check directly","Yes")) | G6: =IFERROR(VLOOKUP(C6,'Broker Fees'!$A$4:$G$9,7,0),0)+IF(D6="",0,IFERROR(VLOOKUP(D6,'Broker Fees'!$A$4:$G$9,7,0),0))+IF(E6="",0,IFERROR(VLOOKUP(E6,'Broker Fees'!$A$4:$G$9,7,0),0)) | H6: Opening all brokers in this combo means meeting each one's minimum deposit separately (this column sums them) and paying each broker's own commission/custody/FX schedule — see Broker Fees sheet. Diversifying across brokers does not lower any individual fee. | I6: =VLOOKUP($A6,'Capital Gains Tax'!$A$4:$D$9,2,0) | J6: =VLOOKUP($A6,'Capital Gains Tax'!$A$4:$D$9,3,0)
A7: US | B7: Exante | C7: Exante | F7: =IF(OR(IF(C7="","", IFERROR(INDEX('Tax Residency Eligibility'!$B$4:$G$9,MATCH(C7,'Tax Residency Eligibility'!$A$4:$A$9,0),MATCH($A7,'Tax Residency Eligibility'!$B$3:$G$3,0)),"?"))="N",IF(D7="","", IFERROR(INDEX('Tax Residency Eligibility'!$B$4:$G$9,MATCH(D7,'Tax Residency Eligibility'!$A$4:$A$9,0),MATCH($A7,'Tax Residency Eligibility'!$B$3:$G$3,0)),"?"))="N",IF(E7="","", IFERROR(INDEX('Tax Residency Eligibility'!$B$4:$G$9,MATCH(E7,'Tax Residency Eligibility'!$A$4:$A$9,0),MATCH($A7,'Tax Residency Eligibility'!$B$3:$G$3,0)),"?"))="N"),"No",IF(OR(IF(C7="","", IFERROR(INDEX('Tax Residency Eligibility'!$B$4:$G$9,MATCH(C7,'Tax Residency Eligibility'!$A$4:$A$9,0),MATCH($A7,'Tax Residency Eligibility'!$B$3:$G$3,0)),"?"))="Check",IF(D7="","", IFERROR(INDEX('Tax Residency Eligibility'!$B$4:$G$9,MATCH(D7,'Tax Residency Eligibility'!$A$4:$A$9,0),MATCH($A7,'Tax Residency Eligibility'!$B$3:$G$3,0)),"?"))="Check",IF(E7="","", IFERROR(INDEX('Tax Residency Eligibility'!$B$4:$G$9,MATCH(E7,'Tax Residency Eligibility'!$A$4:$A$9,0),MATCH($A7,'Tax Residency Eligibility'!$B$3:$G$3,0)),"?"))="Check"),"Check directly","Yes")) | G7: =IFERROR(VLOOKUP(C7,'Broker Fees'!$A$4:$G$9,7,0),0)+IF(D7="",0,IFERROR(VLOOKUP(D7,'Broker Fees'!$A$4:$G$9,7,0),0))+IF(E7="",0,IFERROR(VLOOKUP(E7,'Broker Fees'!$A$4:$G$9,7,0),0)) | H7: Opening all brokers in this combo means meeting each one's minimum deposit separately (this column sums them) and paying each broker's own commission/custody/FX schedule — see Broker Fees sheet. Diversifying across brokers does not lower any individual fee. | I7: =VLOOKUP($A7,'Capital Gains Tax'!$A$4:$D$9,2,0) | J7: =VLOOKUP($A7,'Capital Gains Tax'!$A$4:$D$9,3,0)
A8: US | B8: Swissquote | C8: Swissquote | F8: =IF(OR(IF(C8="","", IFERROR(INDEX('Tax Residency Eligibility'!$B$4:$G$9,MATCH(C8,'Tax Residency Eligibility'!$A$4:$A$9,0),MATCH($A8,'Tax Residency Eligibility'!$B$3:$G$3,0)),"?"))="N",IF(D8="","", IFERROR(INDEX('Tax Residency Eligibility'!$B$4:$G$9,MATCH(D8,'Tax Residency Eligibility'!$A$4:$A$9,0),MATCH($A8,'Tax Residency Eligibility'!$B$3:$G$3,0)),"?"))="N",IF(E8="","", IFERROR(INDEX('Tax Residency Eligibility'!$B$4:$G$9,MATCH(E8,'Tax Residency Eligibility'!$A$4:$A$9,0),MATCH($A8,'Tax Residency Eligibility'!$B$3:$G$3,0)),"?"))="N"),"No",IF(OR(IF(C8="","", IFERROR(INDEX('Tax Residency Eligibility'!$B$4:$G$9,MATCH(C8,'Tax Residency Eligibility'!$A$4:$A$9,0),MATCH($A8,'Tax Residency Eligibility'!$B$3:$G$3,0)),"?"))="Check",IF(D8="","", IFERROR(INDEX('Tax Residency Eligibility'!$B$4:$G$9,MATCH(D8,'Tax Residency Eligibility'!$A$4:$A$9,0),MATCH($A8,'Tax Residency Eligibility'!$B$3:$G$3,0)),"?"))="Check",IF(E8="","", IFERROR(INDEX('Tax Residency Eligibility'!$B$4:$G$9,MATCH(E8,'Tax Residency Eligibility'!$A$4:$A$9,0),MATCH($A8,'Tax Residency Eligibility'!$B$3:$G$3,0)),"?"))="Check"),"Check directly","Yes")) | G8: =IFERROR(VLOOKUP(C8,'Broker Fees'!$A$4:$G$9,7,0),0)+IF(D8="",0,IFERROR(VLOOKUP(D8,'Broker Fees'!$A$4:$G$9,7,0),0))+IF(E8="",0,IFERROR(VLOOKUP(E8,'Broker Fees'!$A$4:$G$9,7,0),0)) | H8: Opening all brokers in this combo means meeting each one's minimum deposit separately (this column sums them) and paying each broker's own commission/custody/FX schedule — see Broker Fees sheet. Diversifying across brokers does not lower any individual fee. | I8: =VLOOKUP($A8,'Capital Gains Tax'!$A$4:$D$9,2,0) | J8: =VLOOKUP($A8,'Capital Gains Tax'!$A$4:$D$9,3,0)
A9: US | B9: XTB | C9: XTB | F9: =IF(OR(IF(C9="","", IFERROR(INDEX('Tax Residency Eligibility'!$B$4:$G$9,MATCH(C9,'Tax Residency Eligibility'!$A$4:$A$9,0),MATCH($A9,'Tax Residency Eligibility'!$B$3:$G$3,0)),"?"))="N",IF(D9="","", IFERROR(INDEX('Tax Residency Eligibility'!$B$4:$G$9,MATCH(D9,'Tax Residency Eligibility'!$A$4:$A$9,0),MATCH($A9,'Tax Residency Eligibility'!$B$3:$G$3,0)),"?"))="N",IF(E9="","", IFERROR(INDEX('Tax Residency Eligibility'!$B$4:$G$9,MATCH(E9,'Tax Residency Eligibility'!$A$4:$A$9,0),MATCH($A9,'Tax Residency Eligibility'!$B$3:$G$3,0)),"?"))="N"),"No",IF(OR(IF(C9="","", IFERROR(INDEX('Tax Residency Eligibility'!$B$4:$G$9,MATCH(C9,'Tax Residency Eligibility'!$A$4:$A$9,0),MATCH($A9,'Tax Residency Eligibility'!$B$3:$G$3,0)),"?"))="Check",IF(D9="","", IFERROR(INDEX('Tax Residency Eligibility'!$B$4:$G$9,MATCH(D9,'Tax Residency Eligibility'!$A$4:$A$9,0),MATCH($A9,'Tax Residency Eligibility'!$B$3:$G$3,0)),"?"))="Check",IF(E9="","", IFERROR(INDEX('Tax Residency Eligibility'!$B$4:$G$9,MATCH(E9,'Tax Residency Eligibility'!$A$4:$A$9,0),MATCH($A9,'Tax Residency Eligibility'!$B$3:$G$3,0)),"?"))="Check"),"Check directly","Yes")) | G9: =IFERROR(VLOOKUP(C9,'Broker Fees'!$A$4:$G$9,7,0),0)+IF(D9="",0,IFERROR(VLOOKUP(D9,'Broker Fees'!$A$4:$G$9,7,0),0))+IF(E9="",0,IFERROR(VLOOKUP(E9,'Broker Fees'!$A$4:$G$9,7,0),0)) | H9: Opening all brokers in this combo means meeting each one's minimum deposit separately (this column sums them) and paying each broker's own commission/custody/FX schedule — see Broker Fees sheet. Diversifying across brokers does not lower any individual fee. | I9: =VLOOKUP($A9,'Capital Gains Tax'!$A$4:$D$9,2,0) | J9: =VLOOKUP($A9,'Capital Gains Tax'!$A$4:$D$9,3,0)
A10: US | B10: IBKR+Saxo | C10: IBKR | D10: Saxo | F10: =IF(OR(IF(C10="","", IFERROR(INDEX('Tax Residency Eligibility'!$B$4:$G$9,MATCH(C10,'Tax Residency Eligibility'!$A$4:$A$9,0),MATCH($A10,'Tax Residency Eligibility'!$B$3:$G$3,0)),"?"))="N",IF(D10="","", IFERROR(INDEX('Tax Residency Eligibility'!$B$4:$G$9,MATCH(D10,'Tax Residency Eligibility'!$A$4:$A$9,0),MATCH($A10,'Tax Residency Eligibility'!$B$3:$G$3,0)),"?"))="N",IF(E10="","", IFERROR(INDEX('Tax Residency Eligibility'!$B$4:$G$9,MATCH(E10,'Tax Residency Eligibility'!$A$4:$A$9,0),MATCH($A10,'Tax Residency Eligibility'!$B$3:$G$3,0)),"?"))="N"),"No",IF(OR(IF(C10="","", IFERROR(INDEX('Tax Residency Eligibility'!$B$4:$G$9,MATCH(C10,'Tax Residency Eligibility'!$A$4:$A$9,0),MATCH($A10,'Tax Residency Eligibility'!$B$3:$G$3,0)),"?"))="Check",IF(D10="","", IFERROR(INDEX('Tax Residency Eligibility'!$B$4:$G$9,MATCH(D10,'Tax Residency Eligibility'!$A$4:$A$9,0),MATCH($A10,'Tax Residency Eligibility'!$B$3:$G$3,0)),"?"))="Check",IF(E10="","", IFERROR(INDEX('Tax Residency Eligibility'!$B$4:$G$9,MATCH(E10,'Tax Residency Eligibility'!$A$4:$A$9,0),MATCH($A10,'Tax Residency Eligibility'!$B$3:$G$3,0)),"?"))="Check"),"Check directly","Yes")) | G10: =IFERROR(VLOOKUP(C10,'Broker Fees'!$A$4:$G$9,7,0),0)+IF(D10="",0,IFERROR(VLOOKUP(D10,'Broker Fees'!$A$4:$G$9,7,0),0))+IF(E10="",0,IFERROR(VLOOKUP(E10,'Broker Fees'!$A$4:$G$9,7,0),0)) | H10: Opening all brokers in this combo means meeting each one's minimum deposit separately (this column sums them) and paying each broker's own commission/custody/FX schedule — see Broker Fees sheet. Diversifying across brokers does not lower any individual fee. | I10: =VLOOKUP($A10,'Capital Gains Tax'!$A$4:$D$9,2,0) | J10: =VLOOKUP($A10,'Capital Gains Tax'!$A$4:$D$9,3,0)
A11: US | B11: IBKR+Wio | C11: IBKR | D11: Wio | F11: =IF(OR(IF(C11="","", IFERROR(INDEX('Tax Residency Eligibility'!$B$4:$G$9,MATCH(C11,'Tax Residency Eligibility'!$A$4:$A$9,0),MATCH($A11,'Tax Residency Eligibility'!$B$3:$G$3,0)),"?"))="N",IF(D11="","", IFERROR(INDEX('Tax Residency Eligibility'!$B$4:$G$9,MATCH(D11,'Tax Residency Eligibility'!$A$4:$A$9,0),MATCH($A11,'Tax Residency Eligibility'!$B$3:$G$3,0)),"?"))="N",IF(E11="","", IFERROR(INDEX('Tax Residency Eligibility'!$B$4:$G$9,MATCH(E11,'Tax Residency Eligibility'!$A$4:$A$9,0),MATCH($A11,'Tax Residency Eligibility'!$B$3:$G$3,0)),"?"))="N"),"No",IF(OR(IF(C11="","", IFERROR(INDEX('Tax Residency Eligibility'!$B$4:$G$9,MATCH(C11,'Tax Residency Eligibility'!$A$4:$A$9,0),MATCH($A11,'Tax Residency Eligibility'!$B$3:$G$3,0)),"?"))="Check",IF(D11="","", IFERROR(INDEX('Tax Residency Eligibility'!$B$4:$G$9,MATCH(D11,'Tax Residency Eligibility'!$A$4:$A$9,0),MATCH($A11,'Tax Residency Eligibility'!$B$3:$G$3,0)),"?"))="Check",IF(E11="","", IFERROR(INDEX('Tax Residency Eligibility'!$B$4:$G$9,MATCH(E11,'Tax Residency Eligibility'!$A$4:$A$9,0),MATCH($A11,'Tax Residency Eligibility'!$B$3:$G$3,0)),"?"))="Check"),"Check directly","Yes")) | G11: =IFERROR(VLOOKUP(C11,'Broker Fees'!$A$4:$G$9,7,0),0)+IF(D11="",0,IFERROR(VLOOKUP(D11,'Broker Fees'!$A$4:$G$9,7,0),0))+IF(E11="",0,IFERROR(VLOOKUP(E11,'Broker Fees'!$A$4:$G$9,7,0),0)) | H11: Opening all brokers in this combo means meeting each one's minimum deposit separately (this column sums them) and paying each broker's own commission/custody/FX schedule — see Broker Fees sheet. Diversifying across brokers does not lower any individual fee. | I11: =VLOOKUP($A11,'Capital Gains Tax'!$A$4:$D$9,2,0) | J11: =VLOOKUP($A11,'Capital Gains Tax'!$A$4:$D$9,3,0)
A12: US | B12: IBKR+Exante | C12: IBKR | D12: Exante | F12: =IF(OR(IF(C12="","", IFERROR(INDEX('Tax Residency Eligibility'!$B$4:$G$9,MATCH(C12,'Tax Residency Eligibility'!$A$4:$A$9,0),MATCH($A12,'Tax Residency Eligibility'!$B$3:$G$3,0)),"?"))="N",IF(D12="","", IFERROR(INDEX('Tax Residency Eligibility'!$B$4:$G$9,MATCH(D12,'Tax Residency Eligibility'!$A$4:$A$9,0),MATCH($A12,'Tax Residency Eligibility'!$B$3:$G$3,0)),"?"))="N",IF(E12="","", IFERROR(INDEX('Tax Residency Eligibility'!$B$4:$G$9,MATCH(E12,'Tax Residency Eligibility'!$A$4:$A$9,0),MATCH($A12,'Tax Residency Eligibility'!$B$3:$G$3,0)),"?"))="N"),"No",IF(OR(IF(C12="","", IFERROR(INDEX('Tax Residency Eligibility'!$B$4:$G$9,MATCH(C12,'Tax Residency Eligibility'!$A$4:$A$9,0),MATCH($A12,'Tax Residency Eligibility'!$B$3:$G$3,0)),"?"))="Check",IF(D12="","", IFERROR(INDEX('Tax Residency Eligibility'!$B$4:$G$9,MATCH(D12,'Tax Residency Eligibility'!$A$4:$A$9,0),MATCH($A12,'Tax Residency Eligibility'!$B$3:$G$3,0)),"?"))="Check",IF(E12="","", IFERROR(INDEX('Tax Residency Eligibility'!$B$4:$G$9,MATCH(E12,'Tax Residency Eligibility'!$A$4:$A$9,0),MATCH($A12,'Tax Residency Eligibility'!$B$3:$G$3,0)),"?"))="Check"),"Check directly","Yes")) | G12: =IFERROR(VLOOKUP(C12,'Broker Fees'!$A$4:$G$9,7,0),0)+IF(D12="",0,IFERROR(VLOOKUP(D12,'Broker Fees'!$A$4:$G$9,7,0),0))+IF(E12="",0,IFERROR(VLOOKUP(E12,'Broker Fees'!$A$4:$G$9,7,0),0)) | H12: Opening all brokers in this combo means meeting each one's minimum deposit separately (this column sums them) and paying each broker's own commission/custody/FX schedule — see Broker Fees sheet. Diversifying across brokers does not lower any individual fee. | I12: =VLOOKUP($A12,'Capital Gains Tax'!$A$4:$D$9,2,0) | J12: =VLOOKUP($A12,'Capital Gains Tax'!$A$4:$D$9,3,0)
A13: US | B13: IBKR+Swissquote | C13: IBKR | D13: Swissquote | F13: =IF(OR(IF(C13="","", IFERROR(INDEX('Tax Residency Eligibility'!$B$4:$G$9,MATCH(C13,'Tax Residency Eligibility'!$A$4:$A$9,0),MATCH($A13,'Tax Residency Eligibility'!$B$3:$G$3,0)),"?"))="N",IF(D13="","", IFERROR(INDEX('Tax Residency Eligibility'!$B$4:$G$9,MATCH(D13,'Tax Residency Eligibility'!$A$4:$A$9,0),MATCH($A13,'Tax Residency Eligibility'!$B$3:$G$3,0)),"?"))="N",IF(E13="","", IFERROR(INDEX('Tax Residency Eligibility'!$B$4:$G$9,MATCH(E13,'Tax Residency Eligibility'!$A$4:$A$9,0),MATCH($A13,'Tax Residency Eligibility'!$B$3:$G$3,0)),"?"))="N"),"No",IF(OR(IF(C13="","", IFERROR(INDEX('Tax Residency Eligibility'!$B$4:$G$9,MATCH(C13,'Tax Residency Eligibility'!$A$4:$A$9,0),MATCH($A13,'Tax Residency Eligibility'!$B$3:$G$3,0)),"?"))="Check",IF(D13="","", IFERROR(INDEX('Tax Residency Eligibility'!$B$4:$G$9,MATCH(D13,'Tax Residency Eligibility'!$A$4:$A$9,0),MATCH($A13,'Tax Residency Eligibility'!$B$3:$G$3,0)),"?"))="Check",IF(E13="","", IFERROR(INDEX('Tax Residency Eligibility'!$B$4:$G$9,MATCH(E13,'Tax Residency Eligibility'!$A$4:$A$9,0),MATCH($A13,'Tax Residency Eligibility'!$B$3:$G$3,0)),"?"))="Check"),"Check directly","Yes")) | G13: =IFERROR(VLOOKUP(C13,'Broker Fees'!$A$4:$G$9,7,0),0)+IF(D13="",0,IFERROR(VLOOKUP(D13,'Broker Fees'!$A$4:$G$9,7,0),0))+IF(E13="",0,IFERROR(VLOOKUP(E13,'Broker Fees'!$A$4:$G$9,7,0),0)) | H13: Opening all brokers in this combo means meeting each one's minimum deposit separately (this column sums them) and paying each broker's own commission/custody/FX schedule — see Broker Fees sheet. Diversifying across brokers does not lower any individual fee. | I13: =VLOOKUP($A13,'Capital Gains Tax'!$A$4:$D$9,2,0) | J13: =VLOOKUP($A13,'Capital Gains Tax'!$A$4:$D$9,3,0)
A14: US | B14: IBKR+XTB | C14: IBKR | D14: XTB | F14: =IF(OR(IF(C14="","", IFERROR(INDEX('Tax Residency Eligibility'!$B$4:$G$9,MATCH(C14,'Tax Residency Eligibility'!$A$4:$A$9,0),MATCH($A14,'Tax Residency Eligibility'!$B$3:$G$3,0)),"?"))="N",IF(D14="","", IFERROR(INDEX('Tax Residency Eligibility'!$B$4:$G$9,MATCH(D14,'Tax Residency Eligibility'!$A$4:$A$9,0),MATCH($A14,'Tax Residency Eligibility'!$B$3:$G$3,0)),"?"))="N",IF(E14="","", IFERROR(INDEX('Tax Residency Eligibility'!$B$4:$G$9,MATCH(E14,'Tax Residency Eligibility'!$A$4:$A$9,0),MATCH($A14,'Tax Residency Eligibility'!$B$3:$G$3,0)),"?"))="N"),"No",IF(OR(IF(C14="","", IFERROR(INDEX('Tax Residency Eligibility'!$B$4:$G$9,MATCH(C14,'Tax Residency Eligibility'!$A$4:$A$9,0),MATCH($A14,'Tax Residency Eligibility'!$B$3:$G$3,0)),"?"))="Check",IF(D14="","", IFERROR(INDEX('Tax Residency Eligibility'!$B$4:$G$9,MATCH(D14,'Tax Residency Eligibility'!$A$4:$A$9,0),MATCH($A14,'Tax Residency Eligibility'!$B$3:$G$3,0)),"?"))="Check",IF(E14="","", IFERROR(INDEX('Tax Residency Eligibility'!$B$4:$G$9,MATCH(E14,'Tax Residency Eligibility'!$A$4:$A$9,0),MATCH($A14,'Tax Residency Eligibility'!$B$3:$G$3,0)),"?"))="Check"),"Check directly","Yes")) | G14: =IFERROR(VLOOKUP(C14,'Broker Fees'!$A$4:$G$9,7,0),0)+IF(D14="",0,IFERROR(VLOOKUP(D14,'Broker Fees'!$A$4:$G$9,7,0),0))+IF(E14="",0,IFERROR(VLOOKUP(E14,'Broker Fees'!$A$4:$G$9,7,0),0)) | H14: Opening all brokers in this combo means meeting each one's minimum deposit separately (this column sums them) and paying each broker's own commission/custody/FX schedule — see Broker Fees sheet. Diversifying across brokers does not lower any individual fee. | I14: =VLOOKUP($A14,'Capital Gains Tax'!$A$4:$D$9,2,0) | J14: =VLOOKUP($A14,'Capital Gains Tax'!$A$4:$D$9,3,0)
A15: US | B15: Saxo+Wio | C15: Saxo | D15: Wio | F15: =IF(OR(IF(C15="","", IFERROR(INDEX('Tax Residency Eligibility'!$B$4:$G$9,MATCH(C15,'Tax Residency Eligibility'!$A$4:$A$9,0),MATCH($A15,'Tax Residency Eligibility'!$B$3:$G$3,0)),"?"))="N",IF(D15="","", IFERROR(INDEX('Tax Residency Eligibility'!$B$4:$G$9,MATCH(D15,'Tax Residency Eligibility'!$A$4:$A$9,0),MATCH($A15,'Tax Residency Eligibility'!$B$3:$G$3,0)),"?"))="N",IF(E15="","", IFERROR(INDEX('Tax Residency Eligibility'!$B$4:$G$9,MATCH(E15,'Tax Residency Eligibility'!$A$4:$A$9,0),MATCH($A15,'Tax Residency Eligibility'!$B$3:$G$3,0)),"?"))="N"),"No",IF(OR(IF(C15="","", IFERROR(INDEX('Tax Residency Eligibility'!$B$4:$G$9,MATCH(C15,'Tax Residency Eligibility'!$A$4:$A$9,0),MATCH($A15,'Tax Residency Eligibility'!$B$3:$G$3,0)),"?"))="Check",IF(D15="","", IFERROR(INDEX('Tax Residency Eligibility'!$B$4:$G$9,MATCH(D15,'Tax Residency Eligibility'!$A$4:$A$9,0),MATCH($A15,'Tax Residency Eligibility'!$B$3:$G$3,0)),"?"))="Check",IF(E15="","", IFERROR(INDEX('Tax Residency Eligibility'!$B$4:$G$9,MATCH(E15,'Tax Residency Eligibility'!$A$4:$A$9,0),MATCH($A15,'Tax Residency Eligibility'!$B$3:$G$3,0)),"?"))="Check"),"Check directly","Yes")) | G15: =IFERROR(VLOOKUP(C15,'Broker Fees'!$A$4:$G$9,7,0),0)+IF(D15="",0,IFERROR(VLOOKUP(D15,'Broker Fees'!$A$4:$G$9,7,0),0))+IF(E15="",0,IFERROR(VLOOKUP(E15,'Broker Fees'!$A$4:$G$9,7,0),0)) | H15: Opening all brokers in this combo means meeting each one's minimum deposit separately (this column sums them) and paying each broker's own commission/custody/FX schedule — see Broker Fees sheet. Diversifying across brokers does not lower any individual fee. | I15: =VLOOKUP($A15,'Capital Gains Tax'!$A$4:$D$9,2,0) | J15: =VLOOKUP($A15,'Capital Gains Tax'!$A$4:$D$9,3,0)
A16: US | B16: Saxo+Exante | C16: Saxo | D16: Exante | F16: =IF(OR(IF(C16="","", IFERROR(INDEX('Tax Residency Eligibility'!$B$4:$G$9,MATCH(C16,'Tax Residency Eligibility'!$A$4:$A$9,0),MATCH($A16,'Tax Residency Eligibility'!$B$3:$G$3,0)),"?"))="N",IF(D16="","", IFERROR(INDEX('Tax Residency Eligibility'!$B$4:$G$9,MATCH(D16,'Tax Residency Eligibility'!$A$4:$A$9,0),MATCH($A16,'Tax Residency Eligibility'!$B$3:$G$3,0)),"?"))="N",IF(E16="","", IFERROR(INDEX('Tax Residency Eligibility'!$B$4:$G$9,MATCH(E16,'Tax Residency Eligibility'!$A$4:$A$9,0),MATCH($A16,'Tax Residency Eligibility'!$B$3:$G$3,0)),"?"))="N"),"No",IF(OR(IF(C16="","", IFERROR(INDEX('Tax Residency Eligibility'!$B$4:$G$9,MATCH(C16,'Tax Residency Eligibility'!$A$4:$A$9,0),MATCH($A16,'Tax Residency Eligibility'!$B$3:$G$3,0)),"?"))="Check",IF(D16="","", IFERROR(INDEX('Tax Residency Eligibility'!$B$4:$G$9,MATCH(D16,'Tax Residency Eligibility'!$A$4:$A$9,0),MATCH($A16,'Tax Residency Eligibility'!$B$3:$G$3,0)),"?"))="Check",IF(E16="","", IFERROR(INDEX('Tax Residency Eligibility'!$B$4:$G$9,MATCH(E16,'Tax Residency Eligibility'!$A$4:$A$9,0),MATCH($A16,'Tax Residency Eligibility'!$B$3:$G$3,0)),"?"))="Check"),"Check directly","Yes")) | G16: =IFERROR(VLOOKUP(C16,'Broker Fees'!$A$4:$G$9,7,0),0)+IF(D16="",0,IFERROR(VLOOKUP(D16,'Broker Fees'!$A$4:$G$9,7,0),0))+IF(E16="",0,IFERROR(VLOOKUP(E16,'Broker Fees'!$A$4:$G$9,7,0),0)) | H16: Opening all brokers in this combo means meeting each one's minimum deposit separately (this column sums them) and paying each broker's own commission/custody/FX schedule — see Broker Fees sheet. Diversifying across brokers does not lower any individual fee. | I16: =VLOOKUP($A16,'Capital Gains Tax'!$A$4:$D$9,2,0) | J16: =VLOOKUP($A16,'Capital Gains Tax'!$A$4:$D$9,3,0)
A17: US | B17: Saxo+Swissquote | C17: Saxo | D17: Swissquote | F17: =IF(OR(IF(C17="","", IFERROR(INDEX('Tax Residency Eligibility'!$B$4:$G$9,MATCH(C17,'Tax Residency Eligibility'!$A$4:$A$9,0),MATCH($A17,'Tax Residency Eligibility'!$B$3:$G$3,0)),"?"))="N",IF(D17="","", IFERROR(INDEX('Tax Residency Eligibility'!$B$4:$G$9,MATCH(D17,'Tax Residency Eligibility'!$A$4:$A$9,0),MATCH($A17,'Tax Residency Eligibility'!$B$3:$G$3,0)),"?"))="N",IF(E17="","", IFERROR(INDEX('Tax Residency Eligibility'!$B$4:$G$9,MATCH(E17,'Tax Residency Eligibility'!$A$4:$A$9,0),MATCH($A17,'Tax Residency Eligibility'!$B$3:$G$3,0)),"?"))="N"),"No",IF(OR(IF(C17="","", IFERROR(INDEX('Tax Residency Eligibility'!$B$4:$G$9,MATCH(C17,'Tax Residency Eligibility'!$A$4:$A$9,0),MATCH($A17,'Tax Residency Eligibility'!$B$3:$G$3,0)),"?"))="Check",IF(D17="","", IFERROR(INDEX('Tax Residency Eligibility'!$B$4:$G$9,MATCH(D17,'Tax Residency Eligibility'!$A$4:$A$9,0),MATCH($A17,'Tax Residency Eligibility'!$B$3:$G$3,0)),"?"))="Check",IF(E17="","", IFERROR(INDEX('Tax Residency Eligibility'!$B$4:$G$9,MATCH(E17,'Tax Residency Eligibility'!$A$4:$A$9,0),MATCH($A17,'Tax Residency Eligibility'!$B$3:$G$3,0)),"?"))="Check"),"Check directly","Yes")) | G17: =IFERROR(VLOOKUP(C17,'Broker Fees'!$A$4:$G$9,7,0),0)+IF(D17="",0,IFERROR(VLOOKUP(D17,'Broker Fees'!$A$4:$G$9,7,0),0))+IF(E17="",0,IFERROR(VLOOKUP(E17,'Broker Fees'!$A$4:$G$9,7,0),0)) | H17: Opening all brokers in this combo means meeting each one's minimum deposit separately (this column sums them) and paying each broker's own commission/custody/FX schedule — see Broker Fees sheet. Diversifying across brokers does not lower any individual fee. | I17: =VLOOKUP($A17,'Capital Gains Tax'!$A$4:$D$9,2,0) | J17: =VLOOKUP($A17,'Capital Gains Tax'!$A$4:$D$9,3,0)
A18: US | B18: Saxo+XTB | C18: Saxo | D18: XTB | F18: =IF(OR(IF(C18="","", IFERROR(INDEX('Tax Residency Eligibility'!$B$4:$G$9,MATCH(C18,'Tax Residency Eligibility'!$A$4:$A$9,0),MATCH($A18,'Tax Residency Eligibility'!$B$3:$G$3,0)),"?"))="N",IF(D18="","", IFERROR(INDEX('Tax Residency Eligibility'!$B$4:$G$9,MATCH(D18,'Tax Residency Eligibility'!$A$4:$A$9,0),MATCH($A18,'Tax Residency Eligibility'!$B$3:$G$3,0)),"?"))="N",IF(E18="","", IFERROR(INDEX('Tax Residency Eligibility'!$B$4:$G$9,MATCH(E18,'Tax Residency Eligibility'!$A$4:$A$9,0),MATCH($A18,'Tax Residency Eligibility'!$B$3:$G$3,0)),"?"))="N"),"No",IF(OR(IF(C18="","", IFERROR(INDEX('Tax Residency Eligibility'!$B$4:$G$9,MATCH(C18,'Tax Residency Eligibility'!$A$4:$A$9,0),MATCH($A18,'Tax Residency Eligibility'!$B$3:$G$3,0)),"?"))="Check",IF(D18="","", IFERROR(INDEX('Tax Residency Eligibility'!$B$4:$G$9,MATCH(D18,'Tax Residency Eligibility'!$A$4:$A$9,0),MATCH($A18,'Tax Residency Eligibility'!$B$3:$G$3,0)),"?"))="Check",IF(E18="","", IFERROR(INDEX('Tax Residency Eligibility'!$B$4:$G$9,MATCH(E18,'Tax Residency Eligibility'!$A$4:$A$9,0),MATCH($A18,'Tax Residency Eligibility'!$B$3:$G$3,0)),"?"))="Check"),"Check directly","Yes")) | G18: =IFERROR(VLOOKUP(C18,'Broker Fees'!$A$4:$G$9,7,0),0)+IF(D18="",0,IFERROR(VLOOKUP(D18,'Broker Fees'!$A$4:$G$9,7,0),0))+IF(E18="",0,IFERROR(VLOOKUP(E18,'Broker Fees'!$A$4:$G$9,7,0),0)) | H18: Opening all brokers in this combo means meeting each one's minimum deposit separately (this column sums them) and paying each broker's own commission/custody/FX schedule — see Broker Fees sheet. Diversifying across brokers does not lower any individual fee. | I18: =VLOOKUP($A18,'Capital Gains Tax'!$A$4:$D$9,2,0) | J18: =VLOOKUP($A18,'Capital Gains Tax'!$A$4:$D$9,3,0)
A19: US | B19: Wio+Exante | C19: Wio | D19: Exante | F19: =IF(OR(IF(C19="","", IFERROR(INDEX('Tax Residency Eligibility'!$B$4:$G$9,MATCH(C19,'Tax Residency Eligibility'!$A$4:$A$9,0),MATCH($A19,'Tax Residency Eligibility'!$B$3:$G$3,0)),"?"))="N",IF(D19="","", IFERROR(INDEX('Tax Residency Eligibility'!$B$4:$G$9,MATCH(D19,'Tax Residency Eligibility'!$A$4:$A$9,0),MATCH($A19,'Tax Residency Eligibility'!$B$3:$G$3,0)),"?"))="N",IF(E19="","", IFERROR(INDEX('Tax Residency Eligibility'!$B$4:$G$9,MATCH(E19,'Tax Residency Eligibility'!$A$4:$A$9,0),MATCH($A19,'Tax Residency Eligibility'!$B$3:$G$3,0)),"?"))="N"),"No",IF(OR(IF(C19="","", IFERROR(INDEX('Tax Residency Eligibility'!$B$4:$G$9,MATCH(C19,'Tax Residency Eligibility'!$A$4:$A$9,0),MATCH($A19,'Tax Residency Eligibility'!$B$3:$G$3,0)),"?"))="Check",IF(D19="","", IFERROR(INDEX('Tax Residency Eligibility'!$B$4:$G$9,MATCH(D19,'Tax Residency Eligibility'!$A$4:$A$9,0),MATCH($A19,'Tax Residency Eligibility'!$B$3:$G$3,0)),"?"))="Check",IF(E19="","", IFERROR(INDEX('Tax Residency Eligibility'!$B$4:$G$9,MATCH(E19,'Tax Residency Eligibility'!$A$4:$A$9,0),MATCH($A19,'Tax Residency Eligibility'!$B$3:$G$3,0)),"?"))="Check"),"Check directly","Yes")) | G19: =IFERROR(VLOOKUP(C19,'Broker Fees'!$A$4:$G$9,7,0),0)+IF(D19="",0,IFERROR(VLOOKUP(D19,'Broker Fees'!$A$4:$G$9,7,0),0))+IF(E19="",0,IFERROR(VLOOKUP(E19,'Broker Fees'!$A$4:$G$9,7,0),0)) | H19: Opening all brokers in this combo means meeting each one's minimum deposit separately (this column sums them) and paying each broker's own commission/custody/FX schedule — see Broker Fees sheet. Diversifying across brokers does not lower any individual fee. | I19: =VLOOKUP($A19,'Capital Gains Tax'!$A$4:$D$9,2,0) | J19: =VLOOKUP($A19,'Capital Gains Tax'!$A$4:$D$9,3,0)
A20: US | B20: Wio+Swissquote | C20: Wio | D20: Swissquote | F20: =IF(OR(IF(C20="","", IFERROR(INDEX('Tax Residency Eligibility'!$B$4:$G$9,MATCH(C20,'Tax Residency Eligibility'!$A$4:$A$9,0),MATCH($A20,'Tax Residency Eligibility'!$B$3:$G$3,0)),"?"))="N",IF(D20="","", IFERROR(INDEX('Tax Residency Eligibility'!$B$4:$G$9,MATCH(D20,'Tax Residency Eligibility'!$A$4:$A$9,0),MATCH($A20,'Tax Residency Eligibility'!$B$3:$G$3,0)),"?"))="N",IF(E20="","", IFERROR(INDEX('Tax Residency Eligibility'!$B$4:$G$9,MATCH(E20,'Tax Residency Eligibility'!$A$4:$A$9,0),MATCH($A20,'Tax Residency Eligibility'!$B$3:$G$3,0)),"?"))="N"),"No",IF(OR(IF(C20="","", IFERROR(INDEX('Tax Residency Eligibility'!$B$4:$G$9,MATCH(C20,'Tax Residency Eligibility'!$A$4:$A$9,0),MATCH($A20,'Tax Residency Eligibility'!$B$3:$G$3,0)),"?"))="Check",IF(D20="","", IFERROR(INDEX('Tax Residency Eligibility'!$B$4:$G$9,MATCH(D20,'Tax Residency Eligibility'!$A$4:$A$9,0),MATCH($A20,'Tax Residency Eligibility'!$B$3:$G$3,0)),"?"))="Check",IF(E20="","", IFERROR(INDEX('Tax Residency Eligibility'!$B$4:$G$9,MATCH(E20,'Tax Residency Eligibility'!$A$4:$A$9,0),MATCH($A20,'Tax Residency Eligibility'!$B$3:$G$3,0)),"?"))="Check"),"Check directly","Yes")) | G20: =IFERROR(VLOOKUP(C20,'Broker Fees'!$A$4:$G$9,7,0),0)+IF(D20="",0,IFERROR(VLOOKUP(D20,'Broker Fees'!$A$4:$G$9,7,0),0))+IF(E20="",0,IFERROR(VLOOKUP(E20,'Broker Fees'!$A$4:$G$9,7,0),0)) | H20: Opening all brokers in this combo means meeting each one's minimum deposit separately (this column sums them) and paying each broker's own commission/custody/FX schedule — see Broker Fees sheet. Diversifying across brokers does not lower any individual fee. | I20: =VLOOKUP($A20,'Capital Gains Tax'!$A$4:$D$9,2,0) | J20: =VLOOKUP($A20,'Capital Gains Tax'!$A$4:$D$9,3,0)
A21: US | B21: Wio+XTB | C21: Wio | D21: XTB | F21: =IF(OR(IF(C21="","", IFERROR(INDEX('Tax Residency Eligibility'!$B$4:$G$9,MATCH(C21,'Tax Residency Eligibility'!$A$4:$A$9,0),MATCH($A21,'Tax Residency Eligibility'!$B$3:$G$3,0)),"?"))="N",IF(D21="","", IFERROR(INDEX('Tax Residency Eligibility'!$B$4:$G$9,MATCH(D21,'Tax Residency Eligibility'!$A$4:$A$9,0),MATCH($A21,'Tax Residency Eligibility'!$B$3:$G$3,0)),"?"))="N",IF(E21="","", IFERROR(INDEX('Tax Residency Eligibility'!$B$4:$G$9,MATCH(E21,'Tax Residency Eligibility'!$A$4:$A$9,0),MATCH($A21,'Tax Residency Eligibility'!$B$3:$G$3,0)),"?"))="N"),"No",IF(OR(IF(C21="","", IFERROR(INDEX('Tax Residency Eligibility'!$B$4:$G$9,MATCH(C21,'Tax Residency Eligibility'!$A$4:$A$9,0),MATCH($A21,'Tax Residency Eligibility'!$B$3:$G$3,0)),"?"))="Check",IF(D21="","", IFERROR(INDEX('Tax Residency Eligibility'!$B$4:$G$9,MATCH(D21,'Tax Residency Eligibility'!$A$4:$A$9,0),MATCH($A21,'Tax Residency Eligibility'!$B$3:$G$3,0)),"?"))="Check",IF(E21="","", IFERROR(INDEX('Tax Residency Eligibility'!$B$4:$G$9,MATCH(E21,'Tax Residency Eligibility'!$A$4:$A$9,0),MATCH($A21,'Tax Residency Eligibility'!$B$3:$G$3,0)),"?"))="Check"),"Check directly","Yes")) | G21: =IFERROR(VLOOKUP(C21,'Broker Fees'!$A$4:$G$9,7,0),0)+IF(D21="",0,IFERROR(VLOOKUP(D21,'Broker Fees'!$A$4:$G$9,7,0),0))+IF(E21="",0,IFERROR(VLOOKUP(E21,'Broker Fees'!$A$4:$G$9,7,0),0)) | H21: Opening all brokers in this combo means meeting each one's minimum deposit separately (this column sums them) and paying each broker's own commission/custody/FX schedule — see Broker Fees sheet. Diversifying across brokers does not lower any individual fee. | I21: =VLOOKUP($A21,'Capital Gains Tax'!$A$4:$D$9,2,0) | J21: =VLOOKUP($A21,'Capital Gains Tax'!$A$4:$D$9,3,0)
... A24: US | B24: Swissquote+XTB | C24: Swissquote | D24: XTB | F24: =IF(OR(IF(C24="","", IFERROR(INDEX('Tax Residency Eligibility'!$B$4:$G$9,MATCH(C24,'Tax Residency Eligibility'!$A$4:$A$9,0),MATCH($A24,'Tax Residency Eligibility'!$B$3:$G$3,0)),"?"))="N",IF(D24="","", IFERROR(INDEX('Tax Residency Eligibility'!$B$4:$G$9,MATCH(D24,'Tax Residency Eligibility'!$A$4:$A$9,0),MATCH($A24,'Tax Residency Eligibility'!$B$3:$G$3,0)),"?"))="N",IF(E24="","", IFERROR(INDEX('Tax Residency Eligibility'!$B$4:$G$9,MATCH(E24,'Tax Residency Eligibility'!$A$4:$A$9,0),MATCH($A24,'Tax Residency Eligibility'!$B$3:$G$3,0)),"?"))="N"),"No",IF(OR(IF(C24="","", IFERROR(INDEX('Tax Residency Eligibility'!$B$4:$G$9,MATCH(C24,'Tax Residency Eligibility'!$A$4:$A$9,0),MATCH($A24,'Tax Residency Eligibility'!$B$3:$G$3,0)),"?"))="Check",IF(D24="","", IFERROR(INDEX('Tax Residency Eligibility'!$B$4:$G$9,MATCH(D24,'Tax Residency Eligibility'!$A$4:$A$9,0),MATCH($A24,'Tax Residency Eligibility'!$B$3:$G$3,0)),"?"))="Check",IF(E24="","", IFERROR(INDEX('Tax Residency Eligibility'!$B$4:$G$9,MATCH(E24,'Tax Residency Eligibility'!$A$4:$A$9,0),MATCH($A24,'Tax Residency Eligibility'!$B$3:$G$3,0)),"?"))="Check"),"Check directly","Yes")) | G24: =IFERROR(VLOOKUP(C24,'Broker Fees'!$A$4:$G$9,7,0),0)+IF(D24="",0,IFERROR(VLOOKUP(D24,'Broker Fees'!$A$4:$G$9,7,0),0))+IF(E24="",0,IFERROR(VLOOKUP(E24,'Broker Fees'!$A$4:$G$9,7,0),0)) | H24: Opening all brokers in this combo means meeting each one's minimum deposit separately (this column sums them) and paying each broker's own commission/custody/FX schedule — see Broker Fees sheet. Diversifying across brokers does not lower any individual fee. | I24: =VLOOKUP($A24,'Capital Gains Tax'!$A$4:$D$9,2,0) | J24: =VLOOKUP($A24,'Capital Gains Tax'!$A$4:$D$9,3,0)
A25: US | B25: IBKR+Saxo+Wio | C25: IBKR | D25: Saxo | E25: Wio | F25: =IF(OR(IF(C25="","", IFERROR(INDEX('Tax Residency Eligibility'!$B$4:$G$9,MATCH(C25,'Tax Residency Eligibility'!$A$4:$A$9,0),MATCH($A25,'Tax Residency Eligibility'!$B$3:$G$3,0)),"?"))="N",IF(D25="","", IFERROR(INDEX('Tax Residency Eligibility'!$B$4:$G$9,MATCH(D25,'Tax Residency Eligibility'!$A$4:$A$9,0),MATCH($A25,'Tax Residency Eligibility'!$B$3:$G$3,0)),"?"))="N",IF(E25="","", IFERROR(INDEX('Tax Residency Eligibility'!$B$4:$G$9,MATCH(E25,'Tax Residency Eligibility'!$A$4:$A$9,0),MATCH($A25,'Tax Residency Eligibility'!$B$3:$G$3,0)),"?"))="N"),"No",IF(OR(IF(C25="","", IFERROR(INDEX('Tax Residency Eligibility'!$B$4:$G$9,MATCH(C25,'Tax Residency Eligibility'!$A$4:$A$9,0),MATCH($A25,'Tax Residency Eligibility'!$B$3:$G$3,0)),"?"))="Check",IF(D25="","", IFERROR(INDEX('Tax Residency Eligibility'!$B$4:$G$9,MATCH(D25,'Tax Residency Eligibility'!$A$4:$A$9,0),MATCH($A25,'Tax Residency Eligibility'!$B$3:$G$3,0)),"?"))="Check",IF(E25="","", IFERROR(INDEX('Tax Residency Eligibility'!$B$4:$G$9,MATCH(E25,'Tax Residency Eligibility'!$A$4:$A$9,0),MATCH($A25,'Tax Residency Eligibility'!$B$3:$G$3,0)),"?"))="Check"),"Check directly","Yes")) | G25: =IFERROR(VLOOKUP(C25,'Broker Fees'!$A$4:$G$9,7,0),0)+IF(D25="",0,IFERROR(VLOOKUP(D25,'Broker Fees'!$A$4:$G$9,7,0),0))+IF(E25="",0,IFERROR(VLOOKUP(E25,'Broker Fees'!$A$4:$G$9,7,0),0)) | H25: Opening all brokers in this combo means meeting each one's minimum deposit separately (this column sums them) and paying each broker's own commission/custody/FX schedule — see Broker Fees sheet. Diversifying across brokers does not lower any individual fee. | I25: =VLOOKUP($A25,'Capital Gains Tax'!$A$4:$D$9,2,0) | J25: =VLOOKUP($A25,'Capital Gains Tax'!$A$4:$D$9,3,0)
A26: US | B26: IBKR+Saxo+Exante | C26: IBKR | D26: Saxo | E26: Exante | F26: =IF(OR(IF(C26="","", IFERROR(INDEX('Tax Residency Eligibility'!$B$4:$G$9,MATCH(C26,'Tax Residency Eligibility'!$A$4:$A$9,0),MATCH($A26,'Tax Residency Eligibility'!$B$3:$G$3,0)),"?"))="N",IF(D26="","", IFERROR(INDEX('Tax Residency Eligibility'!$B$4:$G$9,MATCH(D26,'Tax Residency Eligibility'!$A$4:$A$9,0),MATCH($A26,'Tax Residency Eligibility'!$B$3:$G$3,0)),"?"))="N",IF(E26="","", IFERROR(INDEX('Tax Residency Eligibility'!$B$4:$G$9,MATCH(E26,'Tax Residency Eligibility'!$A$4:$A$9,0),MATCH($A26,'Tax Residency Eligibility'!$B$3:$G$3,0)),"?"))="N"),"No",IF(OR(IF(C26="","", IFERROR(INDEX('Tax Residency Eligibility'!$B$4:$G$9,MATCH(C26,'Tax Residency Eligibility'!$A$4:$A$9,0),MATCH($A26,'Tax Residency Eligibility'!$B$3:$G$3,0)),"?"))="Check",IF(D26="","", IFERROR(INDEX('Tax Residency Eligibility'!$B$4:$G$9,MATCH(D26,'Tax Residency Eligibility'!$A$4:$A$9,0),MATCH($A26,'Tax Residency Eligibility'!$B$3:$G$3,0)),"?"))="Check",IF(E26="","", IFERROR(INDEX('Tax Residency Eligibility'!$B$4:$G$9,MATCH(E26,'Tax Residency Eligibility'!$A$4:$A$9,0),MATCH($A26,'Tax Residency Eligibility'!$B$3:$G$3,0)),"?"))="Check"),"Check directly","Yes")) | G26: =IFERROR(VLOOKUP(C26,'Broker Fees'!$A$4:$G$9,7,0),0)+IF(D26="",0,IFERROR(VLOOKUP(D26,'Broker Fees'!$A$4:$G$9,7,0),0))+IF(E26="",0,IFERROR(VLOOKUP(E26,'Broker Fees'!$A$4:$G$9,7,0),0)) | H26: Opening all brokers in this combo means meeting each one's minimum deposit separately (this column sums them) and paying each broker's own commission/custody/FX schedule — see Broker Fees sheet. Diversifying across brokers does not lower any individual fee. | I26: =VLOOKUP($A26,'Capital Gains Tax'!$A$4:$D$9,2,0) | J26: =VLOOKUP($A26,'Capital Gains Tax'!$A$4:$D$9,3,0)
A27: US | B27: IBKR+Saxo+Swissquote | C27: IBKR | D27: Saxo | E27: Swissquote | F27: =IF(OR(IF(C27="","", IFERROR(INDEX('Tax Residency Eligibility'!$B$4:$G$9,MATCH(C27,'Tax Residency Eligibility'!$A$4:$A$9,0),MATCH($A27,'Tax Residency Eligibility'!$B$3:$G$3,0)),"?"))="N",IF(D27="","", IFERROR(INDEX('Tax Residency Eligibility'!$B$4:$G$9,MATCH(D27,'Tax Residency Eligibility'!$A$4:$A$9,0),MATCH($A27,'Tax Residency Eligibility'!$B$3:$G$3,0)),"?"))="N",IF(E27="","", IFERROR(INDEX('Tax Residency Eligibility'!$B$4:$G$9,MATCH(E27,'Tax Residency Eligibility'!$A$4:$A$9,0),MATCH($A27,'Tax Residency Eligibility'!$B$3:$G$3,0)),"?"))="N"),"No",IF(OR(IF(C27="","", IFERROR(INDEX('Tax Residency Eligibility'!$B$4:$G$9,MATCH(C27,'Tax Residency Eligibility'!$A$4:$A$9,0),MATCH($A27,'Tax Residency Eligibility'!$B$3:$G$3,0)),"?"))="Check",IF(D27="","", IFERROR(INDEX('Tax Residency Eligibility'!$B$4:$G$9,MATCH(D27,'Tax Residency Eligibility'!$A$4:$A$9,0),MATCH($A27,'Tax Residency Eligibility'!$B$3:$G$3,0)),"?"))="Check",IF(E27="","", IFERROR(INDEX('Tax Residency Eligibility'!$B$4:$G$9,MATCH(E27,'Tax Residency Eligibility'!$A$4:$A$9,0),MATCH($A27,'Tax Residency Eligibility'!$B$3:$G$3,0)),"?"))="Check"),"Check directly","Yes")) | G27: =IFERROR(VLOOKUP(C27,'Broker Fees'!$A$4:$G$9,7,0),0)+IF(D27="",0,IFERROR(VLOOKUP(D27,'Broker Fees'!$A$4:$G$9,7,0),0))+IF(E27="",0,IFERROR(VLOOKUP(E27,'Broker Fees'!$A$4:$G$9,7,0),0)) | H27: Opening all brokers in this combo means meeting each one's minimum deposit separately (this column sums them) and paying each broker's own commission/custody/FX schedule — see Broker Fees sheet. Diversifying across brokers does not lower any individual fee. | I27: =VLOOKUP($A27,'Capital Gains Tax'!$A$4:$D$9,2,0) | J27: =VLOOKUP($A27,'Capital Gains Tax'!$A$4:$D$9,3,0)
A28: US | B28: IBKR+Saxo+XTB | C28: IBKR | D28: Saxo | E28: XTB | F28: =IF(OR(IF(C28="","", IFERROR(INDEX('Tax Residency Eligibility'!$B$4:$G$9,MATCH(C28,'Tax Residency Eligibility'!$A$4:$A$9,0),MATCH($A28,'Tax Residency Eligibility'!$B$3:$G$3,0)),"?"))="N",IF(D28="","", IFERROR(INDEX('Tax Residency Eligibility'!$B$4:$G$9,MATCH(D28,'Tax Residency Eligibility'!$A$4:$A$9,0),MATCH($A28,'Tax Residency Eligibility'!$B$3:$G$3,0)),"?"))="N",IF(E28="","", IFERROR(INDEX('Tax Residency Eligibility'!$B$4:$G$9,MATCH(E28,'Tax Residency Eligibility'!$A$4:$A$9,0),MATCH($A28,'Tax Residency Eligibility'!$B$3:$G$3,0)),"?"))="N"),"No",IF(OR(IF(C28="","", IFERROR(INDEX('Tax Residency Eligibility'!$B$4:$G$9,MATCH(C28,'Tax Residency Eligibility'!$A$4:$A$9,0),MATCH($A28,'Tax Residency Eligibility'!$B$3:$G$3,0)),"?"))="Check",IF(D28="","", IFERROR(INDEX('Tax Residency Eligibility'!$B$4:$G$9,MATCH(D28,'Tax Residency Eligibility'!$A$4:$A$9,0),MATCH($A28,'Tax Residency Eligibility'!$B$3:$G$3,0)),"?"))="Check",IF(E28="","", IFERROR(INDEX('Tax Residency Eligibility'!$B$4:$G$9,MATCH(E28,'Tax Residency Eligibility'!$A$4:$A$9,0),MATCH($A28,'Tax Residency Eligibility'!$B$3:$G$3,0)),"?"))="Check"),"Check directly","Yes")) | G28: =IFERROR(VLOOKUP(C28,'Broker Fees'!$A$4:$G$9,7,0),0)+IF(D28="",0,IFERROR(VLOOKUP(D28,'Broker Fees'!$A$4:$G$9,7,0),0))+IF(E28="",0,IFERROR(VLOOKUP(E28,'Broker Fees'!$A$4:$G$9,7,0),0)) | H28: Opening all brokers in this combo means meeting each one's minimum deposit separately (this column sums them) and paying each broker's own commission/custody/FX schedule — see Broker Fees sheet. Diversifying across brokers does not lower any individual fee. | I28: =VLOOKUP($A28,'Capital Gains Tax'!$A$4:$D$9,2,0) | J28: =VLOOKUP($A28,'Capital Gains Tax'!$A$4:$D$9,3,0)
A29: US | B29: IBKR+Wio+Exante | C29: IBKR | D29: Wio | E29: Exante | F29: =IF(OR(IF(C29="","", IFERROR(INDEX('Tax Residency Eligibility'!$B$4:$G$9,MATCH(C29,'Tax Residency Eligibility'!$A$4:$A$9,0),MATCH($A29,'Tax Residency Eligibility'!$B$3:$G$3,0)),"?"))="N",IF(D29="","", IFERROR(INDEX('Tax Residency Eligibility'!$B$4:$G$9,MATCH(D29,'Tax Residency Eligibility'!$A$4:$A$9,0),MATCH($A29,'Tax Residency Eligibility'!$B$3:$G$3,0)),"?"))="N",IF(E29="","", IFERROR(INDEX('Tax Residency Eligibility'!$B$4:$G$9,MATCH(E29,'Tax Residency Eligibility'!$A$4:$A$9,0),MATCH($A29,'Tax Residency Eligibility'!$B$3:$G$3,0)),"?"))="N"),"No",IF(OR(IF(C29="","", IFERROR(INDEX('Tax Residency Eligibility'!$B$4:$G$9,MATCH(C29,'Tax Residency Eligibility'!$A$4:$A$9,0),MATCH($A29,'Tax Residency Eligibility'!$B$3:$G$3,0)),"?"))="Check",IF(D29="","", IFERROR(INDEX('Tax Residency Eligibility'!$B$4:$G$9,MATCH(D29,'Tax Residency Eligibility'!$A$4:$A$9,0),MATCH($A29,'Tax Residency Eligibility'!$B$3:$G$3,0)),"?"))="Check",IF(E29="","", IFERROR(INDEX('Tax Residency Eligibility'!$B$4:$G$9,MATCH(E29,'Tax Residency Eligibility'!$A$4:$A$9,0),MATCH($A29,'Tax Residency Eligibility'!$B$3:$G$3,0)),"?"))="Check"),"Check directly","Yes")) | G29: =IFERROR(VLOOKUP(C29,'Broker Fees'!$A$4:$G$9,7,0),0)+IF(D29="",0,IFERROR(VLOOKUP(D29,'Broker Fees'!$A$4:$G$9,7,0),0))+IF(E29="",0,IFERROR(VLOOKUP(E29,'Broker Fees'!$A$4:$G$9,7,0),0)) | H29: Opening all brokers in this combo means meeting each one's minimum deposit separately (this column sums them) and paying each broker's own commission/custody/FX schedule — see Broker Fees sheet. Diversifying across brokers does not lower any individual fee. | I29: =VLOOKUP($A29,'Capital Gains Tax'!$A$4:$D$9,2,0) | J29: =VLOOKUP($A29,'Capital Gains Tax'!$A$4:$D$9,3,0)
A30: US | B30: IBKR+Wio+Swissquote | C30: IBKR | D30: Wio | E30: Swissquote | F30: =IF(OR(IF(C30="","", IFERROR(INDEX('Tax Residency Eligibility'!$B$4:$G$9,MATCH(C30,'Tax Residency Eligibility'!$A$4:$A$9,0),MATCH($A30,'Tax Residency Eligibility'!$B$3:$G$3,0)),"?"))="N",IF(D30="","", IFERROR(INDEX('Tax Residency Eligibility'!$B$4:$G$9,MATCH(D30,'Tax Residency Eligibility'!$A$4:$A$9,0),MATCH($A30,'Tax Residency Eligibility'!$B$3:$G$3,0)),"?"))="N",IF(E30="","", IFERROR(INDEX('Tax Residency Eligibility'!$B$4:$G$9,MATCH(E30,'Tax Residency Eligibility'!$A$4:$A$9,0),MATCH($A30,'Tax Residency Eligibility'!$B$3:$G$3,0)),"?"))="N"),"No",IF(OR(IF(C30="","", IFERROR(INDEX('Tax Residency Eligibility'!$B$4:$G$9,MATCH(C30,'Tax Residency Eligibility'!$A$4:$A$9,0),MATCH($A30,'Tax Residency Eligibility'!$B$3:$G$3,0)),"?"))="Check",IF(D30="","", IFERROR(INDEX('Tax Residency Eligibility'!$B$4:$G$9,MATCH(D30,'Tax Residency Eligibility'!$A$4:$A$9,0),MATCH($A30,'Tax Residency Eligibility'!$B$3:$G$3,0)),"?"))="Check",IF(E30="","", IFERROR(INDEX('Tax Residency Eligibility'!$B$4:$G$9,MATCH(E30,'Tax Residency Eligibility'!$A$4:$A$9,0),MATCH($A30,'Tax Residency Eligibility'!$B$3:$G$3,0)),"?"))="Check"),"Check directly","Yes")) | G30: =IFERROR(VLOOKUP(C30,'Broker Fees'!$A$4:$G$9,7,0),0)+IF(D30="",0,IFERROR(VLOOKUP(D30,'Broker Fees'!$A$4:$G$9,7,0),0))+IF(E30="",0,IFERROR(VLOOKUP(E30,'Broker Fees'!$A$4:$G$9,7,0),0)) | H30: Opening all brokers in this combo means meeting each one's minimum deposit separately (this column sums them) and paying each broker's own commission/custody/FX schedule — see Broker Fees sheet. Diversifying across brokers does not lower any individual fee. | I30: =VLOOKUP($A30,'Capital Gains Tax'!$A$4:$D$9,2,0) | J30: =VLOOKUP($A30,'Capital Gains Tax'!$A$4:$D$9,3,0)
